
# Created by Ruins mod version 17.2 Ingame Parser
# authoring Player: JT122406

# TEMPLATE PARAMETER SETTINGS:
#
# criterion expression specifying mod ids required to load template
# may include plus (AND), minus (AND NOT), comma (OR), and parentheses
# all required mods listed must be present; no prohibited mods can be
requiredMods=
#
# likelihood this template will be chosen relative to all others
# e.g., a weight=6 template is chosen 3X as often as one with weight=2
weight=1
#
# list of dimensions in which this template may spawn, even if generic
# one or more dimension names, separated by commas (blank = all)
dimensionsToSpawnIn=
#
# list of other biomes in which this template may spawn
# biome corresponding to directory is always assumed, listed or not
# generic templates should leave this list empty
biomesToSpawnIn=
#
# criterion expression specifying types of biome where template spawns
# this is in addition to those explicitly listed as biomesToSpawnIn
# generic templates should leave this list empty
biomeTypesToSpawnIn=
#
# list of biomes in which this template may not spawn
# takes precedence over biomeTypesToSpawnIn, but NOT biomesToSpawnIn
# should be empty if biomeTypesToSpawnIn is empty
biomesToNotSpawnIn=
#
# depth template is pushed down into the surface when built
# offset is min/max range of random additional bury depth
embed_into_distance=0
random_height_offset=0,0
#
# whitelist/blacklist of block types on which template may be built
# specify one, not both; leave the other empty (both empty = allow all)
acceptable_target_blocks=
unacceptable_target_blocks=flowing_water,water,flowing_lava,lava
#
# size of template (#layers, #rows per layer, #blocks per row)
dimensions=10,20,16
#
# max number of missing blocks allowed in surface beneath template
allowable_overhang=0
#
# depth/height limit affected by terrain leveling
# also maximum bumpiness tolerated in surface beneath template
max_leveling=2
#
# padding applied to all sides of template horizontal footprint
# expands area affected by terrain leveling (-1 = no leveling)
leveling_buffer=0
#
# do not rotate template randomly when built (1 = no rotation)
preventRotation=0
#
# treat water/lava blocks as air and protect them from rule0 (1 = yes)
preserve_water=0
preserve_lava=0
#
# minimum distance this template must have from instances of itself
uniqueMinDistance=0
#
# min/max distances this template can be from world spawn (0 = no limit)
# only applies to overworld--i.e., dimension 0
spawnMinDistance=0
spawnMaxDistance=0
#
# other template built nearby whenever this one is
# syntax: <name>;<relativeX>;<maxYdifference>;<relativeZ>[;<chance>]
# may be used more than once to specify multiple neighbors
adjoining_template=

rule1=0,100,biomesoplenty:grass-4
rule2=0,100,biomesoplenty:dirt-2
rule3=0,100,biomesoplenty:leaves_3-14
rule4=0,100,biomesoplenty:log_0-6
rule5=0,100,biomesoplenty:umbran_stairs-2
rule6=0,100,unlimitedchiselworks:chisel_planks_oak_biomesoplenty_planks_0_12-0
rule7=0,100,biomesoplenty:log_3-4
rule8=0,100,biomesoplenty:log_3-8
rule9=0,100,minecraft:redstone_block-0
rule10=0,100,biomesoplenty:planks_0-12
rule11=0,100,minecraft:dirt-0
rule12=0,100,biomesoplenty:log_3-0
rule13=0,100,pixelmon:ghost_lantern-0
rule14=0,100,minecraft:stained_hardened_clay-9
rule15=0,100,chisel:bookshelf_oak-0
rule16=0,100,pixelmon:purple_vending_machine-9
rule17=0,100,pixelmon:purple_cushion_chair-2
rule18=0,100,pixelmon:purple_cushion_chair-0
rule19=0,100,biomesoplenty:wood_slab_1-12
rule20=0,100,pixelmon:purple_cushion_chair-3
rule21=0,100,pixelmon:pc-8
rule22=0,100,minecraft:stained_glass_pane-0
rule23=0,100,pixelmon:healer-0
rule24=0,100,pixelmon:purple_cushion_chair-1
rule25=0,100,props:blockfake-2
rule26=0,100,pixelmon:purple_vending_machine-11
rule27=0,100,biomesoplenty:planks_0-6
rule28=0,100,biomesoplenty:wood_slab_1-4
rule29=0,100,pixelmon:purple_vending_machine-1
rule30=0,100,pixelmon:pc-0
rule31=0,100,pixelmon:shinypokedoll_gulpin-2
rule32=0,100,pixelmon:purple_vending_machine-3
rule33=0,100,biomesoplenty:jacaranda_fence-0
rule34=0,100,ChestGenHook:chests/simple_dungeon:5-2
rule35=0,100,biomesoplenty:wood_slab_0-2
rule36=0,100,biomesoplenty:double_wood_slab_0-2
rule37=0,100,biomesoplenty:double_wood_slab_1-4
rule38=0,100,biomesoplenty:wood_slab_0-10
rule39=0,100,pixelmon:purple_clock-2
rule40=0,100,biomesoplenty:planks_0-2
rule41=0,100,pixelmon:pokecenter_sign-0
rule42=0,100,unlimitedchiselworks:chisel_planks_oak_biomesoplenty_planks_0_2-0

layer
1,1,1,1,1,1,1,1,1,1,1,1,1,1,1,1
1,1,1,1,0,0,0,0,2,2,1,1,1,1,1,1
1,1,1,3,0,0,0,0,0,0,0,1,1,1,1,1
1,1,1,0,0,0,0,0,0,0,0,0,1,1,1,1
1,1,2,0,0,0,0,0,0,0,0,0,2,1,1,1
1,1,2,0,0,0,0,0,0,0,0,0,2,1,1,1
1,1,2,0,0,0,0,0,0,0,0,0,0,1,1,1
1,1,2,0,0,0,0,0,0,0,0,0,0,1,1,4
1,2,0,0,0,0,0,0,0,0,0,0,6,0,0,5
1,2,0,0,0,0,0,0,0,0,0,7,7,0,0,5
1,2,0,0,0,0,0,0,0,0,0,6,7,8,0,5
1,2,0,0,0,0,0,0,0,0,0,0,7,0,0,5
1,2,0,0,0,0,0,0,0,0,0,0,0,0,0,5
1,1,0,0,0,0,0,0,0,0,0,0,0,1,1,4
1,1,0,0,0,0,0,9,0,0,0,9,0,1,1,1
1,1,0,0,0,0,0,0,0,0,0,0,0,1,1,1
1,1,1,0,0,0,0,0,0,0,0,0,0,1,1,1
1,1,1,2,0,0,0,0,0,0,6,2,1,1,1,1
1,1,1,1,0,0,0,0,0,0,2,1,1,1,1,1
1,1,1,1,1,2,2,2,2,2,1,1,1,1,1,1
endlayer

layer
0,0,0,0,0,0,0,0,0,0,0,0,0,0,0,0
0,0,0,0,2,2,2,2,2,2,0,0,0,0,0,0
0,0,0,2,10,10,10,10,10,10,2,0,0,0,0,0
0,0,0,2,10,6,6,6,6,6,10,2,0,0,0,0
0,0,2,2,6,6,6,6,6,6,6,11,2,0,0,0
0,0,2,6,6,6,6,12,6,6,6,6,2,0,0,0
0,0,2,6,6,6,6,6,6,6,6,8,2,0,0,0
0,0,2,6,6,6,6,6,6,6,6,6,2,0,0,0
0,10,10,8,6,10,6,6,6,6,6,6,10,7,4,0
0,10,6,6,6,6,6,6,6,6,6,6,6,7,5,0
0,10,6,6,13,6,6,6,6,6,6,6,6,7,5,0
0,10,6,6,6,6,6,6,6,6,6,6,6,7,5,0
0,10,10,14,10,10,6,6,6,6,6,6,10,7,4,0
0,0,2,10,10,10,6,6,6,6,6,6,2,0,0,0
0,0,2,6,6,6,6,6,6,6,6,8,2,0,0,0
0,0,2,6,6,6,6,8,6,6,6,6,2,0,0,0
0,0,0,2,6,6,6,6,6,6,6,11,2,0,0,0
0,0,0,2,10,6,6,6,6,6,10,2,0,0,0,0
0,0,0,0,2,10,10,10,10,10,2,0,0,0,0,0
0,0,0,0,0,2,2,2,2,2,0,0,0,0,0,0
endlayer

layer
0,0,0,0,0,0,0,0,0,0,0,0,0,0,0,0
0,0,0,0,10,10,10,10,10,10,0,0,0,0,0,0
0,0,0,10,10,15,15,16,15,15,10,0,0,0,0,0
0,0,0,10,15,0,0,0,0,0,15,10,0,0,0,0
0,0,10,10,0,0,0,0,17,0,0,10,10,0,0,0
0,0,10,19,0,0,20,7,19,0,0,18,10,0,0,0
0,0,10,21,0,0,0,19,20,0,19,7,10,0,0,0
0,0,10,19,0,0,0,0,0,0,0,18,10,0,0,0
0,10,7,7,19,7,0,0,0,0,0,0,7,7,0,0
0,22,19,0,0,19,0,0,0,0,0,0,0,22,0,0
0,22,19,23,0,19,0,0,0,0,0,0,0,0,0,0
0,22,19,0,0,19,0,0,0,0,0,0,0,22,0,0
0,10,7,7,19,7,0,0,0,0,0,0,7,7,0,0
0,0,10,19,0,0,0,0,0,0,0,18,10,0,0,0
0,0,10,21,0,0,24,19,0,0,19,7,10,0,0,0
0,0,10,19,0,0,19,7,17,0,0,18,10,0,0,0
0,0,0,10,0,0,24,0,0,0,0,10,10,0,0,25
0,0,0,10,15,0,0,0,0,0,15,10,0,0,0,0
0,0,0,0,10,15,15,26,15,15,10,0,0,0,0,0
0,0,0,0,0,10,10,10,10,10,0,0,0,0,0,0
endlayer

layer
0,0,0,0,0,0,0,0,0,0,0,0,0,0,0,0
0,0,0,0,27,27,27,27,27,27,27,0,0,0,0,0
0,0,0,27,27,15,28,29,28,15,27,27,0,0,0,0
0,0,0,27,28,0,0,0,0,0,28,27,0,0,0,0
0,0,27,27,0,0,0,0,0,0,0,27,27,0,0,0
0,0,27,0,0,0,0,0,0,0,0,0,22,0,0,0
0,0,27,30,0,0,0,0,0,0,0,0,22,0,0,0
0,0,27,0,0,0,0,0,0,0,0,0,22,0,0,0
0,27,7,7,0,28,0,0,0,0,0,0,7,7,0,0
0,22,0,0,0,0,0,0,0,0,0,0,0,22,0,0
0,22,0,0,0,0,0,0,0,0,0,0,0,0,0,0
0,22,31,0,0,0,0,0,0,0,0,0,0,22,0,0
0,27,7,7,0,28,0,0,0,0,0,0,7,7,0,0
0,0,27,0,0,0,0,0,0,0,0,0,22,0,0,0
0,0,27,30,0,0,0,0,0,0,0,0,22,0,0,0
0,0,27,0,0,0,0,0,0,0,0,0,22,0,0,0
0,0,27,27,0,0,0,0,0,0,0,27,27,0,0,0
0,0,0,27,28,0,0,0,0,0,28,27,0,0,0,0
0,0,0,27,27,15,28,32,28,15,27,27,0,0,0,0
0,0,0,0,27,27,27,27,27,27,27,0,0,0,0,0
endlayer

layer
0,0,0,0,0,0,0,0,0,0,0,0,0,0,0,0
0,0,0,0,27,27,27,27,27,27,27,0,0,0,0,0
0,0,0,27,27,28,0,0,0,28,27,27,0,0,0,0
0,0,0,27,0,0,0,0,0,0,0,27,0,0,0,0
0,0,27,27,0,0,0,0,0,0,0,27,27,0,0,0
0,0,27,19,0,0,0,0,0,0,0,0,22,0,0,0
0,0,27,19,0,0,0,0,0,0,0,0,22,0,0,0
0,0,27,19,0,0,0,0,0,0,0,0,22,0,0,0
0,27,7,7,0,0,0,0,0,0,0,33,7,7,0,0
0,22,0,0,0,0,0,0,0,0,0,0,0,22,0,0
0,22,0,0,0,0,0,0,0,0,0,0,0,22,0,0
0,22,0,0,0,0,0,0,0,0,0,0,0,22,0,0
0,27,7,7,0,0,0,0,0,0,0,33,7,7,0,0
0,0,27,19,0,0,0,0,0,0,0,0,22,0,0,0
0,0,27,19,0,0,0,0,0,0,0,0,22,0,0,0
0,0,27,19,0,0,0,0,0,0,0,0,22,0,0,0
0,0,27,27,0,0,0,0,0,0,0,27,27,0,0,0
0,0,0,27,0,0,0,0,0,0,0,27,0,0,0,0
0,0,0,27,27,28,0,0,0,28,27,27,0,0,0,0
0,0,0,0,27,27,27,27,27,27,27,0,0,0,0,0
endlayer

layer
0,0,0,0,0,0,0,0,0,0,0,0,0,0,0,0
0,0,0,0,22,22,22,22,22,22,22,0,0,0,0,0
0,0,0,22,22,0,0,0,0,0,22,22,0,0,0,0
0,0,0,22,0,0,0,0,0,0,0,22,0,0,0,0
0,0,27,22,0,0,0,0,0,0,0,22,27,0,0,0
0,0,27,0,0,0,0,0,0,0,0,0,27,0,0,0
0,0,27,34,0,0,0,0,0,0,0,0,27,0,0,0
0,0,27,0,0,0,0,0,0,0,0,0,27,35,0,0
0,27,37,28,0,0,0,0,0,0,0,35,36,36,0,0
0,27,0,0,0,0,0,0,0,0,0,0,38,12,36,0
0,27,39,0,0,0,0,0,0,0,0,0,38,12,38,0
0,27,0,0,0,0,0,0,0,0,0,0,38,12,36,0
0,27,37,28,0,0,0,0,0,0,0,35,36,36,0,0
0,0,27,0,0,0,0,0,0,0,0,0,27,35,0,0
0,0,27,34,0,0,0,0,0,0,0,0,27,0,0,0
0,0,27,0,0,0,0,0,0,0,0,0,27,0,0,0
0,0,27,22,0,0,0,0,0,0,0,22,27,0,0,0
0,0,0,22,0,0,0,0,0,0,0,22,0,0,0,0
0,0,0,22,22,0,0,0,0,0,22,22,0,0,0,0
0,0,0,0,22,22,22,22,22,22,22,0,0,0,0,0
endlayer

layer
0,0,0,0,0,0,0,0,0,0,0,0,0,0,0,0
0,0,0,0,40,40,40,40,40,40,40,0,0,0,0,0
0,0,0,40,40,0,0,0,0,0,40,40,0,0,0,0
0,0,40,40,0,0,0,0,0,0,0,40,40,0,0,0
0,0,40,40,0,0,0,0,0,0,0,40,40,40,0,0
0,40,40,0,0,0,0,0,0,0,0,0,40,40,0,0
0,40,40,0,0,0,0,0,0,0,0,0,40,40,0,0
0,40,40,0,0,0,0,0,0,0,0,0,22,0,0,0
40,40,13,0,0,0,0,0,0,0,0,0,22,0,0,0
40,40,15,0,0,0,0,0,0,0,0,0,22,35,0,0
40,40,15,0,0,0,0,0,0,0,0,0,22,41,0,0
40,40,15,0,0,0,0,0,0,0,0,0,22,35,0,0
40,40,13,0,0,0,0,0,0,0,0,0,22,0,0,0
0,40,40,0,0,0,0,0,0,0,0,0,22,0,0,0
0,40,40,0,0,0,0,0,0,0,0,0,40,40,0,0
0,40,40,0,0,0,0,0,0,0,0,0,40,40,0,0
0,0,40,40,0,0,0,0,0,0,0,0,40,40,0,0
0,0,40,40,0,0,0,0,0,0,0,40,40,0,0,0
0,0,0,40,40,0,0,0,0,0,40,40,0,0,0,0
0,0,0,0,40,40,40,40,40,40,40,0,0,0,0,0
endlayer

layer
0,0,0,0,0,0,0,0,0,0,0,0,0,0,0,0
0,0,0,0,0,0,0,0,0,0,0,0,0,0,0,0
0,0,0,0,0,40,40,40,40,40,0,0,0,0,0,0
0,0,0,0,40,40,40,40,40,40,40,0,0,0,0,0
0,0,0,40,40,0,0,0,0,0,40,40,0,0,0,0
0,0,0,40,13,0,0,0,0,0,40,40,40,0,0,0
0,0,40,40,0,0,0,0,0,0,0,13,40,40,0,0
0,0,40,0,0,0,0,0,0,0,0,0,40,40,0,0
0,40,40,0,0,0,0,0,0,0,0,0,40,40,0,0
0,40,28,0,0,0,0,0,0,0,0,0,22,0,0,0
0,40,28,0,0,0,0,0,0,0,0,0,22,0,0,0
0,40,28,0,0,0,0,0,0,0,0,0,22,0,0,0
0,40,40,0,0,0,0,0,0,0,0,0,40,40,0,0
0,0,40,0,0,0,0,0,0,0,0,0,40,40,0,0
0,0,40,40,0,0,0,0,0,0,0,13,40,40,0,0
0,0,0,40,13,0,0,0,0,0,40,40,40,0,0,0
0,0,0,40,40,0,0,0,0,0,40,40,0,0,0,0
0,0,0,0,40,40,40,40,40,40,40,0,0,0,0,0
0,0,0,0,0,40,40,40,40,40,0,0,0,0,0,0
0,0,0,0,0,0,0,0,0,0,0,0,0,0,0,0
endlayer

layer
0,0,0,0,0,0,0,0,0,0,0,0,0,0,0,0
0,0,0,0,0,0,0,0,0,0,0,0,0,0,0,0
0,0,0,0,0,0,0,0,0,0,0,0,0,0,0,0
0,0,0,0,0,0,40,40,40,0,0,0,0,0,0,0
0,0,0,0,0,40,40,40,40,40,0,0,0,0,0,0
0,0,0,0,40,40,40,40,40,40,40,0,0,0,0,0
0,0,0,0,40,40,0,0,0,40,40,40,0,0,0,0
0,0,0,40,40,0,0,0,0,0,40,40,40,0,0,0
0,0,0,40,40,0,0,0,0,0,0,40,40,40,0,0
0,0,40,40,40,0,0,0,0,0,0,0,40,42,0,0
0,0,40,40,40,0,0,0,0,0,0,13,40,42,0,0
0,0,40,40,40,0,0,0,0,0,0,0,40,42,0,0
0,0,0,40,40,0,0,0,0,0,0,40,40,40,0,0
0,0,0,40,40,40,0,0,0,0,40,40,40,0,0,0
0,0,0,0,40,40,0,0,0,40,40,40,0,0,0,0
0,0,0,0,40,40,40,40,40,40,40,0,0,0,0,0
0,0,0,0,0,40,40,40,40,40,0,0,0,0,0,0
0,0,0,0,0,0,40,40,40,0,0,0,0,0,0,0
0,0,0,0,0,0,0,0,0,0,0,0,0,0,0,0
0,0,0,0,0,0,0,0,0,0,0,0,0,0,0,0
endlayer

layer
0,0,0,0,0,0,0,0,0,0,0,0,0,0,0,0
0,0,0,0,0,0,0,0,0,0,0,0,0,0,0,0
0,0,0,0,0,0,0,0,0,0,0,0,0,0,0,0
0,0,0,0,0,0,0,0,0,0,0,0,0,0,0,0
0,0,0,0,0,0,0,0,0,0,0,0,0,0,0,0
0,0,0,0,0,0,40,40,40,0,0,0,0,0,0,0
0,0,0,0,0,40,40,40,40,40,0,0,0,0,0,0
0,0,0,0,0,40,40,40,40,40,40,0,0,0,0,0
0,0,0,0,40,40,40,40,40,40,40,0,0,0,0,0
0,0,0,0,40,40,40,40,40,40,40,40,0,0,0,0
0,0,0,0,40,40,40,40,40,40,40,40,0,0,0,0
0,0,0,0,40,40,40,40,40,40,40,40,0,0,0,0
0,0,0,0,40,40,40,40,40,40,40,0,0,0,0,0
0,0,0,0,0,40,40,40,40,40,40,0,0,0,0,0
0,0,0,0,0,40,40,40,40,40,0,0,0,0,0,0
0,0,0,0,0,0,40,40,40,0,0,0,0,0,0,0
0,0,0,0,0,0,0,0,0,0,0,0,0,0,0,0
0,0,0,0,0,0,0,0,0,0,0,0,0,0,0,0
0,0,0,0,0,0,0,0,0,0,0,0,0,0,0,0
0,0,0,0,0,0,0,0,0,0,0,0,0,0,0,0
endlayer

