
# Created by Ruins mod version 17.2 Ingame Parser
# authoring Player: JT122406

# TEMPLATE PARAMETER SETTINGS:
#
# criterion expression specifying mod ids required to load template
# may include plus (AND), minus (AND NOT), comma (OR), and parentheses
# all required mods listed must be present; no prohibited mods can be
requiredMods=
#
# likelihood this template will be chosen relative to all others
# e.g., a weight=6 template is chosen 3X as often as one with weight=2
weight=1
#
# list of dimensions in which this template may spawn, even if generic
# one or more dimension names, separated by commas (blank = all)
dimensionsToSpawnIn=
#
# list of other biomes in which this template may spawn
# biome corresponding to directory is always assumed, listed or not
# generic templates should leave this list empty
biomesToSpawnIn=
#
# criterion expression specifying types of biome where template spawns
# this is in addition to those explicitly listed as biomesToSpawnIn
# generic templates should leave this list empty
biomeTypesToSpawnIn=
#
# list of biomes in which this template may not spawn
# takes precedence over biomeTypesToSpawnIn, but NOT biomesToSpawnIn
# should be empty if biomeTypesToSpawnIn is empty
biomesToNotSpawnIn=
#
# depth template is pushed down into the surface when built
# offset is min/max range of random additional bury depth
embed_into_distance=0
random_height_offset=0,0
#
# whitelist/blacklist of block types on which template may be built
# specify one, not both; leave the other empty (both empty = allow all)
acceptable_target_blocks=
unacceptable_target_blocks=flowing_water,water,flowing_lava,lava
#
# size of template (#layers, #rows per layer, #blocks per row)
dimensions=10,20,15
#
# max number of missing blocks allowed in surface beneath template
allowable_overhang=0
#
# depth/height limit affected by terrain leveling
# also maximum bumpiness tolerated in surface beneath template
max_leveling=2
#
# padding applied to all sides of template horizontal footprint
# expands area affected by terrain leveling (-1 = no leveling)
leveling_buffer=0
#
# do not rotate template randomly when built (1 = no rotation)
preventRotation=0
#
# treat water/lava blocks as air and protect them from rule0 (1 = yes)
preserve_water=0
preserve_lava=0
#
# minimum distance this template must have from instances of itself
uniqueMinDistance=0
#
# min/max distances this template can be from world spawn (0 = no limit)
# only applies to overworld--i.e., dimension 0
spawnMinDistance=0
spawnMaxDistance=0
#
# other template built nearby whenever this one is
# syntax: <name>;<relativeX>;<maxYdifference>;<relativeZ>[;<chance>]
# may be used more than once to specify multiple neighbors
adjoining_template=

rule1=0,100,biomesoplenty:grass-4
rule2=0,100,biomesoplenty:dirt-2
rule3=0,100,biomesoplenty:leaves_3-14
rule4=0,100,minecraft:redstone_block-0
rule5=0,100,biomesoplenty:log_0-6
rule6=0,100,biomesoplenty:umbran_stairs-2
rule7=0,100,biomesoplenty:log_3-4
rule8=0,100,biomesoplenty:ivy-8
rule9=0,100,biomesoplenty:leaves_0-15
rule10=0,100,biomesoplenty:planks_0-12
rule11=0,100,minecraft:dirt-0
rule12=0,100,biomesoplenty:ivy-4
rule13=0,100,minecraft:piston-9
rule14=0,100,biomesoplenty:wood_slab_1-12
rule15=0,100,biomesoplenty:log_3-8
rule16=0,100,pixelmon:ghost_lantern-0
rule17=0,100,minecraft:stained_hardened_clay-9
rule18=0,100,cfm:mail_box_birch-0
rule19=0,100,biomesoplenty:ivy-2
rule20=0,100,chisel:bookshelf_oak-0
rule21=0,100,pixelmon:black_cushion_chair-3
rule22=0,100,pixelmon:black_cushion_chair-0
rule23=2,100,minecraft:piston_head-1
rule24=0,100,pixelmon:black_cushion_chair-2
rule25=0,100,pixelmon:pc-8
rule26=0,100,minecraft:stained_glass_pane-0
rule27=0,100,pixelmon:healer-0
rule28=0,100,pixelmon:black_cushion_chair-1
rule29=0,100,props:blockfake-2
rule30=0,100,biomesoplenty:ivy-6
rule31=0,100,biomesoplenty:planks_0-6
rule32=0,100,biomesoplenty:wood_slab_1-4
rule33=0,100,pixelmon:cooking_pot-3
rule34=0,100,pixelmon:pc-0
rule35=0,100,pixelmon:cooking_pot-1
rule36=0,100,biomesoplenty:jacaranda_fence-0
rule37=0,100,pixelmon:orange_clock-2
rule38=0,100,biomesoplenty:wood_slab_0-2
rule39=0,100,biomesoplenty:double_wood_slab_0-2
rule40=0,100,biomesoplenty:double_wood_slab_1-4
rule41=0,100,biomesoplenty:log_3-0
rule42=0,100,biomesoplenty:wood_slab_0-10
rule43=0,100,biomesoplenty:planks_0-2
rule44=0,100,biomesoplenty:planks_0-1
rule45=0,100,pixelmon:pokecenter_sign-0
rule46=0,100,biomesoplenty:ivy-1
rule47=0,100,biomesoplenty:ivy-3

layer
1,1,1,1,1,1,1,1,1,1,1,1,1,1,1
1,1,1,0,0,0,0,2,1,1,1,1,1,1,1
1,1,3,0,0,0,0,0,0,0,1,1,1,1,1
1,1,0,0,0,0,0,0,0,0,0,1,1,1,1
1,1,0,0,0,0,0,0,0,0,0,2,1,1,1
1,1,0,0,0,0,4,0,0,0,0,1,1,1,1
1,1,0,0,0,0,4,0,0,0,4,0,1,1,1
1,1,0,0,0,0,0,0,0,0,0,0,1,1,5
2,0,0,0,0,0,0,0,0,0,0,0,0,0,6
2,0,0,0,0,0,0,0,0,0,7,7,0,0,6
2,0,0,0,0,0,0,0,0,0,0,7,0,0,6
2,0,0,0,0,0,0,0,0,0,0,7,0,0,6
2,0,0,0,0,0,0,0,0,0,0,0,0,0,6
1,0,0,0,0,0,0,0,0,0,0,0,1,1,5
1,0,0,0,0,0,4,0,0,0,4,0,1,1,1
1,0,0,0,0,0,4,0,0,0,0,0,1,1,1
1,1,0,0,0,0,0,0,0,0,0,0,1,1,1
1,1,1,0,0,0,0,0,0,0,1,1,1,1,1
1,1,1,0,0,0,0,0,0,1,1,1,1,1,1
1,1,1,1,2,2,2,2,2,1,1,1,1,1,1
endlayer

layer
0,0,0,0,8,0,0,0,8,8,0,0,0,0,0
0,0,0,9,9,2,2,2,9,0,0,0,0,0,0
0,0,3,10,10,10,10,10,10,2,0,0,0,0,0
0,0,10,10,10,10,10,10,10,10,2,0,0,0,0
12,0,10,10,10,10,10,10,10,10,11,2,0,0,0
12,0,10,10,10,10,13,10,10,10,10,0,0,0,0
0,0,10,10,10,10,14,10,10,10,13,10,0,0,0
0,0,10,10,10,10,10,10,10,10,10,10,0,0,0
10,10,15,10,10,10,10,10,10,10,10,10,7,5,0
10,10,10,10,10,10,10,10,10,10,10,10,7,6,0
10,10,10,16,10,10,10,10,10,10,10,10,7,6,0
10,10,10,10,10,10,10,10,10,10,10,10,7,6,0
10,10,17,10,10,10,10,10,10,10,10,10,7,5,0
0,3,10,10,10,10,10,10,10,10,10,10,0,0,0
0,2,10,10,10,10,14,10,10,10,13,10,0,0,0
0,2,10,10,10,10,13,10,10,10,10,2,0,0,18
19,0,2,10,10,10,10,10,10,10,11,2,0,0,0
0,0,0,10,10,10,10,10,10,10,0,0,0,0,0
0,0,0,2,10,10,10,10,10,0,0,0,0,0,0
0,0,0,0,2,2,2,2,2,0,0,0,0,0,0
endlayer

layer
0,0,0,0,8,0,0,8,8,8,0,0,0,0,0
0,0,0,10,10,10,10,10,10,0,0,0,0,0,0
0,0,10,10,20,20,16,20,20,10,0,0,0,0,0
0,0,10,20,0,0,0,0,0,20,10,0,0,0,0
12,10,10,0,0,21,21,0,0,0,10,10,0,0,0
12,10,14,0,0,14,23,22,0,22,22,10,0,0,0
0,10,25,0,0,24,14,22,0,14,23,10,0,0,0
0,10,14,0,0,0,0,0,0,21,22,10,0,0,0
10,7,7,14,7,0,0,0,0,0,0,7,7,0,0
26,14,0,0,14,0,0,0,0,0,0,0,26,0,0
26,14,27,0,14,0,0,0,0,0,0,0,0,0,0
26,14,0,0,14,0,0,0,0,0,0,0,26,0,0
10,7,7,14,7,0,0,0,0,0,0,7,7,0,0
0,10,14,0,0,0,0,0,0,22,22,10,0,0,0
0,10,25,0,0,21,14,22,0,14,23,10,0,0,0
0,10,14,0,0,14,23,28,0,22,22,10,0,0,0
30,0,10,0,0,24,28,0,0,0,10,10,0,0,29
0,0,10,20,0,0,0,0,0,20,10,0,0,0,0
0,0,0,10,20,20,16,20,20,10,0,0,0,0,0
0,0,0,0,10,10,10,10,10,0,0,0,0,0,0
endlayer

layer
0,0,0,8,8,8,0,8,8,8,0,0,0,0,0
0,0,0,31,31,31,31,31,31,31,0,0,0,0,0
0,0,31,31,20,32,33,32,20,31,31,0,0,0,0
0,0,31,32,0,0,0,0,0,32,31,0,0,0,0
12,31,31,0,0,0,0,0,0,0,31,31,0,0,0
12,31,0,0,0,0,0,0,0,0,0,26,0,0,0
0,31,34,0,0,0,0,0,0,0,0,26,0,0,0
0,31,0,0,0,0,0,0,0,0,0,26,0,0,0
31,7,7,0,32,0,0,0,0,0,16,7,7,0,0
26,0,0,0,0,0,0,0,0,0,0,0,26,0,0
26,0,0,0,0,0,0,0,0,0,0,0,0,0,0
26,0,0,0,0,0,0,0,0,0,0,0,26,0,0
31,7,7,0,32,0,0,0,0,0,16,7,7,0,0
0,31,0,0,0,0,0,0,0,0,0,26,0,0,0
0,31,34,0,0,0,0,0,0,0,0,26,0,0,0
0,31,0,0,0,0,0,0,0,0,0,26,0,0,0
30,31,31,0,0,0,0,0,0,0,31,31,0,0,0
0,0,31,32,0,0,0,0,0,32,31,0,0,0,0
0,0,31,31,20,32,35,32,20,31,31,0,0,0,0
0,0,0,31,31,31,31,31,31,31,0,0,0,0,0
endlayer

layer
0,0,0,8,8,8,8,8,8,8,0,0,0,0,0
0,0,0,31,31,31,31,31,31,31,0,0,0,0,0
0,0,31,31,32,0,0,0,32,31,31,0,0,0,0
0,0,31,0,0,0,0,0,0,0,31,0,0,0,0
12,31,31,0,0,0,0,0,0,0,31,31,0,0,0
12,31,14,0,0,0,0,0,0,0,0,26,0,0,0
0,31,14,0,0,0,0,0,0,0,0,26,0,0,0
0,31,14,0,0,0,0,0,0,0,0,26,0,0,0
31,7,7,0,0,0,0,0,0,0,36,7,7,0,0
26,0,0,0,0,0,0,0,0,0,0,0,26,0,0
26,37,0,0,0,0,0,0,0,0,0,0,26,0,0
26,0,0,0,0,0,0,0,0,0,0,0,26,0,0
31,7,7,0,0,0,0,0,0,0,36,7,7,0,0
0,31,14,0,0,0,0,0,0,0,0,26,0,0,0
0,31,14,0,0,0,0,0,0,0,0,26,0,0,0
0,31,14,0,0,0,0,0,0,0,0,26,0,0,0
19,31,31,0,0,0,0,0,0,0,31,31,0,0,0
0,0,31,0,0,0,0,0,0,0,31,0,0,0,0
0,0,31,31,32,0,0,0,32,31,31,0,0,0,0
0,0,0,31,31,31,31,31,31,31,0,0,0,0,0
endlayer

layer
0,0,0,8,8,8,8,0,0,0,0,0,0,0,0
0,0,0,26,26,26,26,26,26,26,0,0,0,0,0
0,0,26,26,0,0,0,0,0,26,26,0,0,0,0
0,0,26,0,0,0,0,0,0,0,26,0,0,0,0
0,31,26,0,0,0,0,0,0,0,26,31,0,0,0
12,31,0,0,0,0,0,0,0,0,0,31,0,0,0
0,31,0,0,0,0,0,0,0,0,0,31,0,0,0
0,31,0,0,0,0,0,0,0,0,0,31,38,0,0
31,40,32,0,0,0,0,0,0,0,38,39,39,0,0
31,0,0,0,0,0,0,0,0,0,0,42,41,39,0
31,0,0,0,0,0,0,0,0,0,0,42,41,42,0
31,0,0,0,0,0,0,0,0,0,0,42,41,39,0
31,40,32,0,0,0,0,0,0,0,38,39,39,0,0
0,31,0,0,0,0,0,0,0,0,0,31,38,0,0
0,31,0,0,0,0,0,0,0,0,0,31,0,0,0
0,31,0,0,0,0,0,0,0,0,0,31,0,0,0
30,31,26,0,0,0,0,0,0,0,26,31,0,0,0
0,0,26,0,0,0,0,0,0,0,26,0,0,0,0
0,0,26,26,0,0,0,0,0,26,26,0,0,0,0
0,0,0,26,26,26,26,26,26,26,0,0,0,0,0
endlayer

layer
0,0,0,8,8,8,8,0,0,0,0,0,0,0,0
0,0,0,43,43,43,43,43,43,43,0,0,0,0,0
0,0,43,43,0,0,0,0,0,43,43,0,0,0,0
0,43,43,0,0,0,0,0,0,0,43,43,0,0,0
0,43,43,0,0,0,0,0,0,0,43,43,43,0,0
43,43,0,0,0,0,0,0,0,0,0,43,43,0,0
43,43,0,0,0,0,0,0,0,0,0,43,43,0,0
43,43,0,0,0,0,0,0,0,0,0,26,0,0,0
44,16,0,0,0,0,0,0,0,0,0,26,0,0,0
44,20,0,0,0,0,0,0,0,0,0,26,38,0,0
44,20,0,0,0,0,0,0,0,0,0,26,45,0,0
44,20,0,0,0,0,0,0,0,0,0,26,38,0,0
44,16,0,0,0,0,0,0,0,0,0,26,0,0,0
43,43,0,0,0,0,0,0,0,0,0,26,8,0,0
43,43,0,0,0,0,0,0,0,0,0,43,43,0,0
43,43,0,0,0,0,0,0,0,0,0,43,43,0,0
30,43,43,0,0,0,0,0,0,0,0,43,43,0,0
0,43,43,0,0,0,0,0,0,0,43,43,0,0,0
0,0,43,43,0,0,0,0,0,43,43,0,0,0,0
0,0,0,43,43,43,43,43,43,43,0,0,0,0,0
endlayer

layer
0,0,0,0,0,0,0,0,0,0,0,0,0,0,0
0,0,0,0,0,0,0,0,0,0,0,0,0,0,0
0,0,0,0,43,43,43,43,43,0,0,0,0,0,0
0,0,0,43,43,43,43,43,43,43,0,0,0,0,0
0,0,43,43,0,0,0,0,0,43,43,0,0,0,0
0,0,43,16,0,0,0,0,0,43,43,43,0,0,0
0,43,43,0,0,0,0,0,0,0,16,43,43,0,0
0,43,0,0,0,0,0,0,0,0,0,43,43,0,0
43,43,0,0,0,0,0,0,0,0,0,43,43,0,0
43,32,0,0,0,0,0,0,0,0,0,26,0,0,0
43,32,0,0,0,0,0,0,0,0,0,26,0,0,0
43,32,0,0,0,0,0,0,0,0,0,26,0,0,0
43,43,0,0,0,0,0,0,0,0,0,43,43,0,0
0,43,0,0,0,0,0,0,0,0,0,43,43,46,0
0,43,43,0,0,0,0,0,0,0,16,43,43,46,0
0,0,43,16,0,0,0,0,0,43,43,43,47,0,0
0,0,43,43,0,0,0,0,0,43,43,19,0,0,0
0,0,0,43,43,43,43,43,43,43,0,0,0,0,0
0,0,0,0,43,43,43,43,43,0,0,0,0,0,0
0,0,0,0,0,0,0,0,0,0,0,0,0,0,0
endlayer

layer
0,0,0,0,0,0,0,0,0,0,0,0,0,0,0
0,0,0,0,0,0,0,0,0,0,0,0,0,0,0
0,0,0,0,0,0,0,0,0,0,0,0,0,0,0
0,0,0,0,0,43,43,43,0,0,0,0,0,0,0
0,0,0,0,43,43,43,43,43,0,0,0,0,0,0
0,0,0,43,43,43,43,43,43,43,0,0,0,0,0
0,0,0,43,43,0,0,0,43,43,43,0,0,0,0
0,0,43,43,0,0,0,0,0,43,43,43,0,0,0
0,0,43,43,0,0,0,0,0,0,43,43,43,0,0
0,43,43,43,0,0,0,0,0,0,0,43,43,0,0
0,43,43,43,0,0,0,0,0,0,16,43,43,0,0
0,43,43,43,0,0,0,0,0,0,0,43,43,0,0
0,0,43,43,0,0,0,0,0,0,43,43,43,0,0
0,0,43,43,43,0,0,0,0,43,43,43,0,0,0
0,0,0,43,43,0,0,0,43,43,43,0,0,0,0
0,0,0,43,43,43,43,43,43,43,0,0,0,0,0
0,0,0,0,43,43,43,43,43,0,0,0,0,0,0
0,0,0,0,0,43,43,43,0,0,0,0,0,0,0
0,0,0,0,0,0,0,0,0,0,0,0,0,0,0
0,0,0,0,0,0,0,0,0,0,0,0,0,0,0
endlayer

layer
0,0,0,0,0,0,0,0,0,0,0,0,0,0,0
0,0,0,0,0,0,0,0,0,0,0,0,0,0,0
0,0,0,0,0,0,0,0,0,0,0,0,0,0,0
0,0,0,0,0,0,0,0,0,0,0,0,0,0,0
0,0,0,0,0,0,0,0,0,0,0,0,0,0,0
0,0,0,0,0,43,43,43,0,0,0,0,0,0,0
0,0,0,0,43,43,43,43,43,0,0,0,0,0,0
0,0,0,0,43,43,43,43,43,43,0,0,0,0,0
0,0,0,43,43,43,43,43,43,43,0,0,0,0,0
0,0,0,43,43,43,43,43,43,43,43,0,0,0,0
0,0,0,43,43,43,43,43,43,43,43,0,0,0,0
0,0,0,43,43,43,43,43,43,43,43,0,0,0,0
0,0,0,43,43,43,43,43,43,43,0,0,0,0,0
0,0,0,0,43,43,43,43,43,43,0,0,0,0,0
0,0,0,0,43,43,43,43,43,0,0,0,0,0,0
0,0,0,0,0,43,43,43,0,0,0,0,0,0,0
0,0,0,0,0,0,0,0,0,0,0,0,0,0,0
0,0,0,0,0,0,0,0,0,0,0,0,0,0,0
0,0,0,0,0,0,0,0,0,0,0,0,0,0,0
0,0,0,0,0,0,0,0,0,0,0,0,0,0,0
endlayer

