
# Created by Ruins mod version 17.2 Ingame Parser
# authoring Player: JT122406

# TEMPLATE PARAMETER SETTINGS:
#
# criterion expression specifying mod ids required to load template
# may include plus (AND), minus (AND NOT), comma (OR), and parentheses
# all required mods listed must be present; no prohibited mods can be
requiredMods=
#
# likelihood this template will be chosen relative to all others
# e.g., a weight=6 template is chosen 3X as often as one with weight=2
weight=1
#
# list of dimensions in which this template may spawn, even if generic
# one or more dimension names, separated by commas (blank = all)
dimensionsToSpawnIn=
#
# list of other biomes in which this template may spawn
# biome corresponding to directory is always assumed, listed or not
# generic templates should leave this list empty
biomesToSpawnIn=
#
# criterion expression specifying types of biome where template spawns
# this is in addition to those explicitly listed as biomesToSpawnIn
# generic templates should leave this list empty
biomeTypesToSpawnIn=
#
# list of biomes in which this template may not spawn
# takes precedence over biomeTypesToSpawnIn, but NOT biomesToSpawnIn
# should be empty if biomeTypesToSpawnIn is empty
biomesToNotSpawnIn=
#
# depth template is pushed down into the surface when built
# offset is min/max range of random additional bury depth
embed_into_distance=0
random_height_offset=0,0
#
# whitelist/blacklist of block types on which template may be built
# specify one, not both; leave the other empty (both empty = allow all)
acceptable_target_blocks=
unacceptable_target_blocks=flowing_water,water,flowing_lava,lava
#
# size of template (#layers, #rows per layer, #blocks per row)
dimensions=10,20,15
#
# max number of missing blocks allowed in surface beneath template
allowable_overhang=0
#
# depth/height limit affected by terrain leveling
# also maximum bumpiness tolerated in surface beneath template
max_leveling=2
#
# padding applied to all sides of template horizontal footprint
# expands area affected by terrain leveling (-1 = no leveling)
leveling_buffer=0
#
# do not rotate template randomly when built (1 = no rotation)
preventRotation=0
#
# treat water/lava blocks as air and protect them from rule0 (1 = yes)
preserve_water=0
preserve_lava=0
#
# minimum distance this template must have from instances of itself
uniqueMinDistance=0
#
# min/max distances this template can be from world spawn (0 = no limit)
# only applies to overworld--i.e., dimension 0
spawnMinDistance=0
spawnMaxDistance=0
#
# other template built nearby whenever this one is
# syntax: <name>;<relativeX>;<maxYdifference>;<relativeZ>[;<chance>]
# may be used more than once to specify multiple neighbors
adjoining_template=

rule1=0,100,biomesoplenty:grass-4
rule2=0,100,minecraft:grass-0
rule3=0,100,biomesoplenty:dirt-2
rule4=0,100,minecraft:dirt-0
rule5=0,100,biomesoplenty:planks_0-12
rule6=0,100,biomesoplenty:leaves_3-14
rule7=0,100,minecraft:redstone_block-0
rule8=0,100,biomesoplenty:log_0-6
rule9=0,100,biomesoplenty:umbran_stairs-2
rule10=0,100,biomesoplenty:log_3-4
rule11=0,100,biomesoplenty:ivy-8
rule12=0,100,biomesoplenty:leaves_0-15
rule13=0,100,biomesoplenty:ivy-4
rule14=0,100,biomesoplenty:wood_slab_1-12
rule15=0,100,biomesoplenty:log_3-8
rule16=0,100,pixelmon:ghost_lantern-0
rule17=0,100,minecraft:stained_hardened_clay-9
rule18=0,100,props:blockprops-0
rule19=0,100,biomesoplenty:ivy-2
rule20=0,100,chisel:bookshelf_oak-0
rule21=0,100,pixelmon:black_cushion_chair-3
rule22=0,100,pixelmon:black_cushion_chair-0
rule23=0,100,pixelmon:black_cushion_chair-2
rule24=0,100,pixelmon:pc-8
rule25=0,100,minecraft:stained_glass_pane-0
rule26=0,100,pixelmon:healer-0
rule27=0,100,pixelmon:black_cushion_chair-1
rule28=0,100,props:blockfake-2
rule29=0,100,biomesoplenty:planks_0-6
rule30=0,100,biomesoplenty:wood_slab_1-4
rule31=0,100,pixelmon:cooking_pot-3
rule32=0,100,pixelmon:pc-0
rule33=0,100,pixelmon:cooking_pot-1
rule34=0,100,biomesoplenty:jacaranda_fence-0
rule35=0,100,pixelmon:orange_clock-2
rule36=0,100,biomesoplenty:wood_slab_0-2
rule37=0,100,biomesoplenty:double_wood_slab_0-2
rule38=0,100,biomesoplenty:double_wood_slab_1-4
rule39=0,100,biomesoplenty:log_3-0
rule40=0,100,biomesoplenty:wood_slab_0-10
rule41=0,100,biomesoplenty:planks_0-2
rule42=0,100,biomesoplenty:planks_0-1
rule43=0,100,pixelmon:pokecenter_sign-0
rule44=0,100,biomesoplenty:ivy-1
rule45=0,100,biomesoplenty:ivy-3

layer
1,1,1,1,1,1,1,1,1,1,1,1,1,1,1
1,1,1,2,2,4,4,3,2,1,1,1,1,1,1
1,1,6,5,0,0,0,0,4,4,1,1,1,1,1
1,1,5,5,5,0,0,0,0,4,4,1,1,1,1
1,1,4,5,0,0,0,0,0,4,4,3,1,1,1
1,1,4,0,0,0,7,0,0,0,4,1,1,1,1
1,1,0,0,0,0,7,0,0,0,7,4,1,1,1
1,1,0,0,0,0,0,0,0,0,0,4,1,1,8
3,0,0,0,0,0,0,0,0,0,0,0,4,4,9
3,0,0,0,0,0,0,0,0,0,10,10,4,2,9
3,0,0,0,0,0,0,0,0,0,0,10,4,2,9
3,0,0,0,0,0,0,0,0,0,0,10,4,2,9
3,0,0,0,0,0,0,0,0,0,0,0,4,4,9
1,2,4,0,0,0,0,0,0,0,0,4,1,1,8
1,4,4,0,0,0,7,0,0,0,7,4,1,1,1
1,4,0,0,0,0,7,0,0,0,0,4,1,1,1
1,1,0,0,0,0,0,0,0,0,0,4,1,1,1
1,1,1,0,0,0,0,0,0,0,1,1,1,1,1
1,1,1,4,4,3,4,0,4,1,1,1,1,1,1
0,1,1,1,3,3,3,3,3,1,1,1,1,1,1
endlayer

layer
0,0,0,0,11,0,0,0,11,11,0,0,0,0,0
0,0,0,12,12,3,3,3,12,0,0,0,0,0,0
0,0,6,5,5,5,5,5,5,1,0,0,0,0,0
0,0,5,5,5,5,5,5,5,5,1,0,0,0,0
13,0,5,5,5,5,5,5,5,5,4,3,0,0,0
13,0,5,5,5,5,14,5,5,5,5,0,0,0,0
0,0,5,5,5,5,14,5,5,5,14,5,0,0,0
0,0,5,5,5,5,5,5,5,5,5,5,0,0,0
5,5,15,5,5,5,5,5,5,5,5,5,10,8,0
5,5,5,5,5,5,5,5,5,5,5,5,10,9,0
5,5,5,16,5,5,5,5,5,5,5,5,10,9,0
5,5,5,5,5,5,5,5,5,5,5,5,10,9,0
5,5,17,5,5,5,5,5,5,5,5,5,10,8,0
0,6,5,5,5,5,5,5,5,5,5,5,0,0,0
0,3,5,5,5,5,14,5,5,5,14,5,0,0,0
0,3,5,5,5,5,14,5,5,5,5,3,0,0,0
19,0,1,5,5,5,5,5,5,5,4,3,0,0,18
0,0,0,5,5,5,5,5,5,5,0,0,0,0,0
0,0,0,1,5,5,5,5,5,0,0,0,0,0,0
0,0,0,0,3,3,3,3,3,0,0,0,0,0,0
endlayer

layer
0,0,0,0,11,0,0,11,11,11,0,0,0,0,0
0,0,0,5,5,5,5,5,5,0,0,0,0,0,0
0,0,5,5,20,20,16,20,20,5,0,0,0,0,0
0,0,5,20,0,0,0,0,0,20,5,0,0,0,0
13,5,5,0,0,21,21,0,0,0,5,5,0,0,0
13,5,14,0,0,14,10,22,0,22,22,5,0,0,0
0,5,24,0,0,23,14,22,0,14,10,5,0,0,0
0,5,14,0,0,0,0,0,0,21,22,5,0,0,0
5,10,10,14,10,0,0,0,0,0,0,10,10,0,0
25,14,0,0,14,0,0,0,0,0,0,0,25,0,0
25,14,26,0,14,0,0,0,0,0,0,0,0,0,0
25,14,0,0,14,0,0,0,0,0,0,0,25,0,0
5,10,10,14,10,0,0,0,0,0,0,10,10,0,0
0,5,14,0,0,0,0,0,0,22,22,5,0,0,0
0,5,24,0,0,21,14,22,0,14,10,5,0,0,0
0,5,14,0,0,14,10,27,0,22,22,5,0,0,0
19,0,5,0,0,23,27,0,0,0,5,5,0,0,28
0,0,5,20,0,0,0,0,0,20,5,0,0,0,0
0,0,0,5,20,20,16,20,20,5,0,0,0,0,0
0,0,0,0,5,5,5,5,5,0,0,0,0,0,0
endlayer

layer
0,0,0,11,11,11,0,11,11,11,0,0,0,0,0
0,0,0,29,29,29,29,29,29,29,0,0,0,0,0
0,0,29,29,20,30,31,30,20,29,29,0,0,0,0
0,0,29,30,0,0,0,0,0,30,29,0,0,0,0
13,29,29,0,0,0,0,0,0,0,29,29,0,0,0
13,29,0,0,0,0,0,0,0,0,0,25,0,0,0
0,29,32,0,0,0,0,0,0,0,0,25,0,0,0
0,29,0,0,0,0,0,0,0,0,0,25,0,0,0
29,10,10,0,30,0,0,0,0,0,16,10,10,0,0
25,0,0,0,0,0,0,0,0,0,0,0,25,0,0
25,0,0,0,0,0,0,0,0,0,0,0,0,0,0
25,0,0,0,0,0,0,0,0,0,0,0,25,0,0
29,10,10,0,30,0,0,0,0,0,16,10,10,0,0
0,29,0,0,0,0,0,0,0,0,0,25,0,0,0
0,29,32,0,0,0,0,0,0,0,0,25,0,0,0
0,29,0,0,0,0,0,0,0,0,0,25,0,0,0
19,29,29,0,0,0,0,0,0,0,29,29,0,0,0
0,0,29,30,0,0,0,0,0,30,29,0,0,0,0
0,0,29,29,20,30,33,30,20,29,29,0,0,0,0
0,0,0,29,29,29,29,29,29,29,0,0,0,0,0
endlayer

layer
0,0,0,11,11,11,11,11,11,11,0,0,0,0,0
0,0,0,29,29,29,29,29,29,29,0,0,0,0,0
0,0,29,29,30,0,0,0,30,29,29,0,0,0,0
0,0,29,0,0,0,0,0,0,0,29,0,0,0,0
13,29,29,0,0,0,0,0,0,0,29,29,0,0,0
13,29,14,0,0,0,0,0,0,0,0,25,0,0,0
0,29,14,0,0,0,0,0,0,0,0,25,0,0,0
0,29,14,0,0,0,0,0,0,0,0,25,0,0,0
29,10,10,0,0,0,0,0,0,0,34,10,10,0,0
25,0,0,0,0,0,0,0,0,0,0,0,25,0,0
25,35,0,0,0,0,0,0,0,0,0,0,25,0,0
25,0,0,0,0,0,0,0,0,0,0,0,25,0,0
29,10,10,0,0,0,0,0,0,0,34,10,10,0,0
0,29,14,0,0,0,0,0,0,0,0,25,0,0,0
0,29,14,0,0,0,0,0,0,0,0,25,0,0,0
0,29,14,0,0,0,0,0,0,0,0,25,0,0,0
19,29,29,0,0,0,0,0,0,0,29,29,0,0,0
0,0,29,0,0,0,0,0,0,0,29,0,0,0,0
0,0,29,29,30,0,0,0,30,29,29,0,0,0,0
0,0,0,29,29,29,29,29,29,29,0,0,0,0,0
endlayer

layer
0,0,0,11,0,11,11,0,0,0,0,0,0,0,0
0,0,0,25,25,25,25,25,25,25,0,0,0,0,0
0,0,25,25,0,0,0,0,0,25,25,0,0,0,0
0,0,25,0,0,0,0,0,0,0,25,0,0,0,0
0,29,25,0,0,0,0,0,0,0,25,29,0,0,0
13,29,0,0,0,0,0,0,0,0,0,29,0,0,0
0,29,0,0,0,0,0,0,0,0,0,29,0,0,0
0,29,0,0,0,0,0,0,0,0,0,29,36,0,0
29,38,30,0,0,0,0,0,0,0,36,37,37,0,0
29,0,0,0,0,0,0,0,0,0,0,40,39,37,0
29,0,0,0,0,0,0,0,0,0,0,40,39,40,0
29,0,0,0,0,0,0,0,0,0,0,40,39,37,0
29,38,30,0,0,0,0,0,0,0,36,37,37,0,0
0,29,0,0,0,0,0,0,0,0,0,29,36,0,0
0,29,0,0,0,0,0,0,0,0,0,29,0,0,0
0,29,0,0,0,0,0,0,0,0,0,29,0,0,0
19,29,25,0,0,0,0,0,0,0,25,29,0,0,0
0,0,25,0,0,0,0,0,0,0,25,0,0,0,0
0,0,25,25,0,0,0,0,0,25,25,0,0,0,0
0,0,0,25,25,25,25,25,25,25,0,0,0,0,0
endlayer

layer
0,0,0,11,11,11,11,0,0,0,0,0,0,0,0
0,0,0,41,41,41,41,41,41,41,0,0,0,0,0
0,0,41,41,0,0,0,0,0,41,41,0,0,0,0
0,41,41,0,0,0,0,0,0,0,41,41,0,0,0
0,41,41,0,0,0,0,0,0,0,41,41,41,0,0
41,41,0,0,0,0,0,0,0,0,0,41,41,0,0
41,41,0,0,0,0,0,0,0,0,0,41,41,0,0
41,41,0,0,0,0,0,0,0,0,0,25,0,0,0
42,16,0,0,0,0,0,0,0,0,0,25,0,0,0
42,20,0,0,0,0,0,0,0,0,0,25,36,0,0
42,20,0,0,0,0,0,0,0,0,0,25,43,0,0
42,20,0,0,0,0,0,0,0,0,0,25,36,0,0
42,16,0,0,0,0,0,0,0,0,0,25,0,0,0
41,41,0,0,0,0,0,0,0,0,0,25,11,0,0
41,41,0,0,0,0,0,0,0,0,0,41,41,0,0
41,41,0,0,0,0,0,0,0,0,0,41,41,0,0
19,41,41,0,0,0,0,0,0,0,0,41,41,0,0
0,41,41,0,0,0,0,0,0,0,41,41,0,0,0
0,0,41,41,0,0,0,0,0,41,41,0,0,0,0
0,0,0,41,41,41,41,41,41,41,0,0,0,0,0
endlayer

layer
0,0,0,0,0,0,0,0,0,0,0,0,0,0,0
0,0,0,0,0,0,0,0,0,0,0,0,0,0,0
0,0,0,0,41,41,41,41,41,0,0,0,0,0,0
0,0,0,41,41,41,41,41,41,41,0,0,0,0,0
0,0,41,41,0,0,0,0,0,41,41,0,0,0,0
0,0,41,16,0,0,0,0,0,41,41,41,0,0,0
0,41,41,0,0,0,0,0,0,0,16,41,41,0,0
0,41,0,0,0,0,0,0,0,0,0,41,41,0,0
41,41,0,0,0,0,0,0,0,0,0,41,41,0,0
41,30,0,0,0,0,0,0,0,0,0,25,0,0,0
41,30,0,0,0,0,0,0,0,0,0,25,0,0,0
41,30,0,0,0,0,0,0,0,0,0,25,0,0,0
41,41,0,0,0,0,0,0,0,0,0,41,41,0,0
0,41,0,0,0,0,0,0,0,0,0,41,41,0,0
0,41,41,0,0,0,0,0,0,0,16,41,41,44,0
0,0,41,16,0,0,0,0,0,41,41,41,45,0,0
0,0,41,41,0,0,0,0,0,41,41,19,0,0,0
0,0,0,41,41,41,41,41,41,41,0,0,0,0,0
0,0,0,0,41,41,41,41,41,0,0,0,0,0,0
0,0,0,0,0,0,0,0,0,0,0,0,0,0,0
endlayer

layer
0,0,0,0,0,0,0,0,0,0,0,0,0,0,0
0,0,0,0,0,0,0,0,0,0,0,0,0,0,0
0,0,0,0,0,0,0,0,0,0,0,0,0,0,0
0,0,0,0,0,41,41,41,0,0,0,0,0,0,0
0,0,0,0,41,41,41,41,41,0,0,0,0,0,0
0,0,0,41,41,41,41,41,41,41,0,0,0,0,0
0,0,0,41,41,0,0,0,41,41,41,0,0,0,0
0,0,41,41,0,0,0,0,0,41,41,41,0,0,0
0,0,41,41,0,0,0,0,0,0,41,41,41,0,0
0,41,41,41,0,0,0,0,0,0,0,41,41,0,0
0,41,41,41,0,0,0,0,0,0,16,41,41,0,0
0,41,41,41,0,0,0,0,0,0,0,41,41,0,0
0,0,41,41,0,0,0,0,0,0,41,41,41,0,0
0,0,41,41,41,0,0,0,0,41,41,41,0,0,0
0,0,0,41,41,0,0,0,41,41,41,0,0,0,0
0,0,0,41,41,41,41,41,41,41,0,0,0,0,0
0,0,0,0,41,41,41,41,41,0,0,0,0,0,0
0,0,0,0,0,41,41,41,0,0,0,0,0,0,0
0,0,0,0,0,0,0,0,0,0,0,0,0,0,0
0,0,0,0,0,0,0,0,0,0,0,0,0,0,0
endlayer

layer
0,0,0,0,0,0,0,0,0,0,0,0,0,0,0
0,0,0,0,0,0,0,0,0,0,0,0,0,0,0
0,0,0,0,0,0,0,0,0,0,0,0,0,0,0
0,0,0,0,0,0,0,0,0,0,0,0,0,0,0
0,0,0,0,0,0,0,0,0,0,0,0,0,0,0
0,0,0,0,0,41,41,41,0,0,0,0,0,0,0
0,0,0,0,41,41,41,41,41,0,0,0,0,0,0
0,0,0,0,41,41,41,41,41,41,0,0,0,0,0
0,0,0,41,41,41,41,41,41,41,0,0,0,0,0
0,0,0,41,41,41,41,41,41,41,41,0,0,0,0
0,0,0,41,41,41,41,41,41,41,41,0,0,0,0
0,0,0,41,41,41,41,41,41,41,41,0,0,0,0
0,0,0,41,41,41,41,41,41,41,0,0,0,0,0
0,0,0,0,41,41,41,41,41,41,0,0,0,0,0
0,0,0,0,41,41,41,41,41,0,0,0,0,0,0
0,0,0,0,0,41,41,41,0,0,0,0,0,0,0
0,0,0,0,0,0,0,0,0,0,0,0,0,0,0
0,0,0,0,0,0,0,0,0,0,0,0,0,0,0
0,0,0,0,0,0,0,0,0,0,0,0,0,0,0
0,0,0,0,0,0,0,0,0,0,0,0,0,0,0
endlayer

